CONFUSION_MATRIX :
[[238   5]
 [ 70 175]]
REPORT :
              precision    recall  f1-score   support
       False       0.77      0.98      0.86       243
        True       0.97      0.71      0.82       245
    accuracy                           0.85       488
   macro avg       0.87      0.85      0.84       488
weighted avg       0.87      0.85      0.84       488
[32mINFO[39m:     127.0.0.1:63765 - "[1mPOST /upload/ HTTP/1.1[22m" [91m500 Internal Server Error
C:\Users\motom\Desktop\Python\Sputnik_voice_autoencoder\venv\lib\site-packages\sklearn\base.py:464: UserWarning: X does not have valid feature names, but SVC was fitted with feature names
  warnings.warn(
[31mERROR[39m:    Exception in ASGI application
Traceback (most recent call last):
  File "C:\Users\motom\Desktop\Python\Sputnik_voice_autoencoder\venv\lib\site-packages\fastapi\encoders.py", line 230, in jsonable_encoder
    data = dict(obj)
TypeError: 'numpy.bool_' object is not iterable
During handling of the above exception, another exception occurred:
Traceback (most recent call last):
  File "C:\Users\motom\Desktop\Python\Sputnik_voice_autoencoder\venv\lib\site-packages\fastapi\encoders.py", line 235, in jsonable_encoder
    data = vars(obj)
TypeError: vars() argument must have __dict__ attribute
The above exception was the direct cause of the following exception:
Traceback (most recent call last):
  File "C:\Users\motom\Desktop\Python\Sputnik_voice_autoencoder\venv\lib\site-packages\uvicorn\protocols\http\h11_impl.py", line 408, in run_asgi
    result = await app(  # type: ignore[func-returns-value]
  File "C:\Users\motom\Desktop\Python\Sputnik_voice_autoencoder\venv\lib\site-packages\uvicorn\middleware\proxy_headers.py", line 84, in __call__
    return await self.app(scope, receive, send)
  File "C:\Users\motom\Desktop\Python\Sputnik_voice_autoencoder\venv\lib\site-packages\fastapi\applications.py", line 289, in __call__
    await super().__call__(scope, receive, send)
  File "C:\Users\motom\Desktop\Python\Sputnik_voice_autoencoder\venv\lib\site-packages\starlette\applications.py", line 122, in __call__
    await self.middleware_stack(scope, receive, send)
  File "C:\Users\motom\Desktop\Python\Sputnik_voice_autoencoder\venv\lib\site-packages\starlette\middleware\errors.py", line 184, in __call__
    raise exc
  File "C:\Users\motom\Desktop\Python\Sputnik_voice_autoencoder\venv\lib\site-packages\starlette\middleware\errors.py", line 162, in __call__
    await self.app(scope, receive, _send)
  File "C:\Users\motom\Desktop\Python\Sputnik_voice_autoencoder\venv\lib\site-packages\starlette\middleware\exceptions.py", line 79, in __call__
    raise exc
  File "C:\Users\motom\Desktop\Python\Sputnik_voice_autoencoder\venv\lib\site-packages\starlette\middleware\exceptions.py", line 68, in __call__
    await self.app(scope, receive, sender)
  File "C:\Users\motom\Desktop\Python\Sputnik_voice_autoencoder\venv\lib\site-packages\fastapi\middleware\asyncexitstack.py", line 20, in __call__
    raise e
  File "C:\Users\motom\Desktop\Python\Sputnik_voice_autoencoder\venv\lib\site-packages\fastapi\middleware\asyncexitstack.py", line 17, in __call__
    await self.app(scope, receive, send)
  File "C:\Users\motom\Desktop\Python\Sputnik_voice_autoencoder\venv\lib\site-packages\starlette\routing.py", line 718, in __call__
    await route.handle(scope, receive, send)
  File "C:\Users\motom\Desktop\Python\Sputnik_voice_autoencoder\venv\lib\site-packages\starlette\routing.py", line 276, in handle
    await self.app(scope, receive, send)
  File "C:\Users\motom\Desktop\Python\Sputnik_voice_autoencoder\venv\lib\site-packages\starlette\routing.py", line 66, in app
    response = await func(request)
  File "C:\Users\motom\Desktop\Python\Sputnik_voice_autoencoder\venv\lib\site-packages\fastapi\routing.py", line 291, in app
    content = await serialize_response(
  File "C:\Users\motom\Desktop\Python\Sputnik_voice_autoencoder\venv\lib\site-packages\fastapi\routing.py", line 179, in serialize_response
    return jsonable_encoder(response_content)
  File "C:\Users\motom\Desktop\Python\Sputnik_voice_autoencoder\venv\lib\site-packages\fastapi\encoders.py", line 195, in jsonable_encoder
    encoded_value = jsonable_encoder(
  File "C:\Users\motom\Desktop\Python\Sputnik_voice_autoencoder\venv\lib\site-packages\fastapi\encoders.py", line 238, in jsonable_encoder
    raise ValueError(errors) from e
ValueError: [TypeError("'numpy.bool_' object is not iterable"), TypeError('vars() argument must have __dict__ attribute')]
[32mINFO[39m:     Shutting down
[32mINFO[39m:     Waiting for application shutdown.
[32mINFO[39m:     Application shutdown complete.
[32mINFO[39m:     Finished server process [[36m7668[39m]