2023-07-22 14:16:48,371 INFO    StreamThr :9548 [internal.py:wandb_internal():86] W&B internal server running at pid: 9548, started at: 2023-07-22 14:16:48.370250
2023-07-22 14:16:48,372 DEBUG   HandlerThread:9548 [handler.py:handle_request():144] handle_request: status
2023-07-22 14:16:48,378 INFO    WriterThread:9548 [datastore.py:open_for_write():85] open: C:\Users\motom\Desktop\Python\Sputnik_voice_autoencoder\wandb\run-20230722_141648-ln7vgcbg\run-ln7vgcbg.wandb
2023-07-22 14:16:48,379 DEBUG   SenderThread:9548 [sender.py:send():369] send: header
2023-07-22 14:16:48,384 DEBUG   SenderThread:9548 [sender.py:send():369] send: run
2023-07-22 14:16:51,805 INFO    SenderThread:9548 [retry.py:__call__():172] Retry attempt failed:
Traceback (most recent call last):
  File "C:\Users\motom\Desktop\Python\Sputnik_voice_autoencoder\venv\lib\site-packages\urllib3\connection.py", line 174, in _new_conn
    conn = connection.create_connection(
  File "C:\Users\motom\Desktop\Python\Sputnik_voice_autoencoder\venv\lib\site-packages\urllib3\util\connection.py", line 72, in create_connection
    for res in socket.getaddrinfo(host, port, family, socket.SOCK_STREAM):
  File "C:\Users\motom\AppData\Local\Programs\Python\Python310\lib\socket.py", line 955, in getaddrinfo
    for res in _socket.getaddrinfo(host, port, family, type, proto, flags):
socket.gaierror: [Errno 11001] getaddrinfo failed

During handling of the above exception, another exception occurred:

Traceback (most recent call last):
  File "C:\Users\motom\Desktop\Python\Sputnik_voice_autoencoder\venv\lib\site-packages\urllib3\connectionpool.py", line 714, in urlopen
    httplib_response = self._make_request(
  File "C:\Users\motom\Desktop\Python\Sputnik_voice_autoencoder\venv\lib\site-packages\urllib3\connectionpool.py", line 403, in _make_request
    self._validate_conn(conn)
  File "C:\Users\motom\Desktop\Python\Sputnik_voice_autoencoder\venv\lib\site-packages\urllib3\connectionpool.py", line 1053, in _validate_conn
    conn.connect()
  File "C:\Users\motom\Desktop\Python\Sputnik_voice_autoencoder\venv\lib\site-packages\urllib3\connection.py", line 363, in connect
    self.sock = conn = self._new_conn()
  File "C:\Users\motom\Desktop\Python\Sputnik_voice_autoencoder\venv\lib\site-packages\urllib3\connection.py", line 186, in _new_conn
    raise NewConnectionError(
urllib3.exceptions.NewConnectionError: <urllib3.connection.HTTPSConnection object at 0x000001D48D8E39D0>: Failed to establish a new connection: [Errno 11001] getaddrinfo failed

During handling of the above exception, another exception occurred:

Traceback (most recent call last):
  File "C:\Users\motom\Desktop\Python\Sputnik_voice_autoencoder\venv\lib\site-packages\requests\adapters.py", line 486, in send
    resp = conn.urlopen(
  File "C:\Users\motom\Desktop\Python\Sputnik_voice_autoencoder\venv\lib\site-packages\urllib3\connectionpool.py", line 798, in urlopen
    retries = retries.increment(
  File "C:\Users\motom\Desktop\Python\Sputnik_voice_autoencoder\venv\lib\site-packages\urllib3\util\retry.py", line 592, in increment
    raise MaxRetryError(_pool, url, error or ResponseError(cause))
urllib3.exceptions.MaxRetryError: HTTPSConnectionPool(host='api.wandb.ai', port=443): Max retries exceeded with url: /graphql (Caused by NewConnectionError('<urllib3.connection.HTTPSConnection object at 0x000001D48D8E39D0>: Failed to establish a new connection: [Errno 11001] getaddrinfo failed'))

During handling of the above exception, another exception occurred:

Traceback (most recent call last):
  File "C:\Users\motom\Desktop\Python\Sputnik_voice_autoencoder\venv\lib\site-packages\wandb\sdk\lib\retry.py", line 131, in __call__
    result = self._call_fn(*args, **kwargs)
  File "C:\Users\motom\Desktop\Python\Sputnik_voice_autoencoder\venv\lib\site-packages\wandb\sdk\internal\internal_api.py", line 321, in execute
    return self.client.execute(*args, **kwargs)  # type: ignore
  File "C:\Users\motom\Desktop\Python\Sputnik_voice_autoencoder\venv\lib\site-packages\wandb\vendor\gql-0.2.0\wandb_gql\client.py", line 52, in execute
    result = self._get_result(document, *args, **kwargs)
  File "C:\Users\motom\Desktop\Python\Sputnik_voice_autoencoder\venv\lib\site-packages\wandb\vendor\gql-0.2.0\wandb_gql\client.py", line 60, in _get_result
    return self.transport.execute(document, *args, **kwargs)
  File "C:\Users\motom\Desktop\Python\Sputnik_voice_autoencoder\venv\lib\site-packages\wandb\sdk\lib\gql_request.py", line 55, in execute
    request = self.session.post(self.url, **post_args)
  File "C:\Users\motom\Desktop\Python\Sputnik_voice_autoencoder\venv\lib\site-packages\requests\sessions.py", line 637, in post
    return self.request("POST", url, data=data, json=json, **kwargs)
  File "C:\Users\motom\Desktop\Python\Sputnik_voice_autoencoder\venv\lib\site-packages\requests\sessions.py", line 589, in request
    resp = self.send(prep, **send_kwargs)
  File "C:\Users\motom\Desktop\Python\Sputnik_voice_autoencoder\venv\lib\site-packages\requests\sessions.py", line 703, in send
    r = adapter.send(request, **kwargs)
  File "C:\Users\motom\Desktop\Python\Sputnik_voice_autoencoder\venv\lib\site-packages\requests\adapters.py", line 519, in send
    raise ConnectionError(e, request=request)
requests.exceptions.ConnectionError: HTTPSConnectionPool(host='api.wandb.ai', port=443): Max retries exceeded with url: /graphql (Caused by NewConnectionError('<urllib3.connection.HTTPSConnection object at 0x000001D48D8E39D0>: Failed to establish a new connection: [Errno 11001] getaddrinfo failed'))
2023-07-22 14:16:53,408 DEBUG   HandlerThread:9548 [handler.py:handle_request():144] handle_request: keepalive
2023-07-22 14:16:58,445 DEBUG   HandlerThread:9548 [handler.py:handle_request():144] handle_request: keepalive
2023-07-22 14:17:03,537 DEBUG   HandlerThread:9548 [handler.py:handle_request():144] handle_request: keepalive
2023-07-22 14:17:05,504 INFO    SenderThread:9548 [dir_watcher.py:__init__():211] watching files in: C:\Users\motom\Desktop\Python\Sputnik_voice_autoencoder\wandb\run-20230722_141648-ln7vgcbg\files
2023-07-22 14:17:05,505 INFO    SenderThread:9548 [sender.py:_start_run_threads():1100] run started: ln7vgcbg with start time 1690010208.375174
2023-07-22 14:17:05,505 DEBUG   SenderThread:9548 [sender.py:send_request():396] send_request: summary_record
2023-07-22 14:17:05,505 DEBUG   HandlerThread:9548 [handler.py:handle_request():144] handle_request: status_report
2023-07-22 14:17:05,506 INFO    SenderThread:9548 [sender.py:_save_file():1354] saving file wandb-summary.json with policy end
2023-07-22 14:17:05,517 DEBUG   HandlerThread:9548 [handler.py:handle_request():144] handle_request: check_version
2023-07-22 14:17:05,517 DEBUG   SenderThread:9548 [sender.py:send_request():396] send_request: check_version
2023-07-22 14:17:05,873 DEBUG   HandlerThread:9548 [handler.py:handle_request():144] handle_request: run_start
2023-07-22 14:17:05,915 DEBUG   HandlerThread:9548 [system_info.py:__init__():31] System info init
2023-07-22 14:17:05,916 DEBUG   HandlerThread:9548 [system_info.py:__init__():46] System info init done
2023-07-22 14:17:05,916 INFO    HandlerThread:9548 [system_monitor.py:start():181] Starting system monitor
2023-07-22 14:17:05,916 INFO    SystemMonitor:9548 [system_monitor.py:_start():145] Starting system asset monitoring threads
2023-07-22 14:17:05,916 INFO    HandlerThread:9548 [system_monitor.py:probe():201] Collecting system info
2023-07-22 14:17:05,921 INFO    SystemMonitor:9548 [interfaces.py:start():190] Started cpu monitoring
2023-07-22 14:17:05,925 DEBUG   HandlerThread:9548 [system_info.py:probe():195] Probing system
2023-07-22 14:17:05,925 INFO    SystemMonitor:9548 [interfaces.py:start():190] Started disk monitoring
2023-07-22 14:17:05,933 INFO    SystemMonitor:9548 [interfaces.py:start():190] Started memory monitoring
2023-07-22 14:17:05,960 INFO    SystemMonitor:9548 [interfaces.py:start():190] Started network monitoring
2023-07-22 14:17:05,985 DEBUG   HandlerThread:9548 [gitlib.py:_init_repo():53] git repository is invalid
2023-07-22 14:17:05,985 DEBUG   HandlerThread:9548 [system_info.py:probe():240] Probing system done
2023-07-22 14:17:05,985 DEBUG   HandlerThread:9548 [system_monitor.py:probe():210] {'os': 'Windows-10-10.0.19045-SP0', 'python': '3.10.4', 'heartbeatAt': '2023-07-22T07:17:05.926265', 'startedAt': '2023-07-22T07:16:48.351198', 'docker': None, 'cuda': None, 'args': ('main:app', '--reload'), 'state': 'running', 'program': '<python with no main file>', 'host': 'WS0001', 'username': 'Solsa', 'executable': 'C:\\Users\\motom\\Desktop\\Python\\Sputnik_voice_autoencoder\\venv\\Scripts\\python.exe', 'cpu_count': 4, 'cpu_count_logical': 8, 'cpu_freq': {'current': 1600.0, 'min': 0.0, 'max': 1800.0}, 'cpu_freq_per_core': [{'current': 1600.0, 'min': 0.0, 'max': 1800.0}], 'disk': {'total': 463.34703063964844, 'used': 414.96863174438477}, 'memory': {'total': 15.810821533203125}}
2023-07-22 14:17:05,985 INFO    HandlerThread:9548 [system_monitor.py:probe():211] Finished collecting system info
2023-07-22 14:17:05,985 INFO    HandlerThread:9548 [system_monitor.py:probe():214] Publishing system info
2023-07-22 14:17:05,985 DEBUG   HandlerThread:9548 [system_info.py:_save_pip():51] Saving list of pip packages installed into the current environment
2023-07-22 14:17:05,986 DEBUG   HandlerThread:9548 [system_info.py:_save_pip():67] Saving pip packages done
2023-07-22 14:17:05,989 INFO    HandlerThread:9548 [system_monitor.py:probe():216] Finished publishing system info
2023-07-22 14:17:06,013 DEBUG   SenderThread:9548 [sender.py:send():369] send: files
2023-07-22 14:17:06,014 INFO    SenderThread:9548 [sender.py:_save_file():1354] saving file wandb-metadata.json with policy now
2023-07-22 14:17:06,029 DEBUG   HandlerThread:9548 [handler.py:handle_request():144] handle_request: stop_status
2023-07-22 14:17:06,030 DEBUG   SenderThread:9548 [sender.py:send_request():396] send_request: stop_status
2023-07-22 14:17:06,387 DEBUG   SenderThread:9548 [sender.py:send():369] send: telemetry
2023-07-22 14:17:06,387 DEBUG   SenderThread:9548 [sender.py:send():369] send: config
2023-07-22 14:17:06,512 INFO    Thread-16 :9548 [dir_watcher.py:_on_file_created():272] file/dir created: C:\Users\motom\Desktop\Python\Sputnik_voice_autoencoder\wandb\run-20230722_141648-ln7vgcbg\files\wandb-summary.json
2023-07-22 14:17:06,512 INFO    Thread-16 :9548 [dir_watcher.py:_on_file_created():272] file/dir created: C:\Users\motom\Desktop\Python\Sputnik_voice_autoencoder\wandb\run-20230722_141648-ln7vgcbg\files\output.log
2023-07-22 14:17:06,513 INFO    Thread-16 :9548 [dir_watcher.py:_on_file_created():272] file/dir created: C:\Users\motom\Desktop\Python\Sputnik_voice_autoencoder\wandb\run-20230722_141648-ln7vgcbg\files\requirements.txt
2023-07-22 14:17:06,514 INFO    Thread-16 :9548 [dir_watcher.py:_on_file_created():272] file/dir created: C:\Users\motom\Desktop\Python\Sputnik_voice_autoencoder\wandb\run-20230722_141648-ln7vgcbg\files\wandb-metadata.json
2023-07-22 14:17:06,644 INFO    wandb-upload_0:9548 [upload_job.py:push():133] Uploaded file C:\Users\motom\AppData\Local\Temp\tmp6yrc7pjpwandb\dmhtgze0-wandb-metadata.json
2023-07-22 14:17:08,529 INFO    Thread-16 :9548 [dir_watcher.py:_on_file_modified():289] file/dir modified: C:\Users\motom\Desktop\Python\Sputnik_voice_autoencoder\wandb\run-20230722_141648-ln7vgcbg\files\output.log
2023-07-22 14:17:11,128 DEBUG   HandlerThread:9548 [handler.py:handle_request():144] handle_request: status_report
2023-07-22 14:17:12,555 INFO    Thread-16 :9548 [dir_watcher.py:_on_file_modified():289] file/dir modified: C:\Users\motom\Desktop\Python\Sputnik_voice_autoencoder\wandb\run-20230722_141648-ln7vgcbg\files\output.log
2023-07-22 14:17:16,224 DEBUG   HandlerThread:9548 [handler.py:handle_request():144] handle_request: status_report
2023-07-22 14:17:21,036 DEBUG   HandlerThread:9548 [handler.py:handle_request():144] handle_request: stop_status
2023-07-22 14:17:21,036 DEBUG   SenderThread:9548 [sender.py:send_request():396] send_request: stop_status
2023-07-22 14:17:21,259 DEBUG   HandlerThread:9548 [handler.py:handle_request():144] handle_request: status_report
2023-07-22 14:17:21,658 INFO    Thread-16 :9548 [dir_watcher.py:_on_file_modified():289] file/dir modified: C:\Users\motom\Desktop\Python\Sputnik_voice_autoencoder\wandb\run-20230722_141648-ln7vgcbg\files\config.yaml
2023-07-22 14:17:26,576 DEBUG   HandlerThread:9548 [handler.py:handle_request():144] handle_request: status_report
2023-07-22 14:17:31,717 DEBUG   HandlerThread:9548 [handler.py:handle_request():144] handle_request: status_report
2023-07-22 14:17:36,033 DEBUG   HandlerThread:9548 [handler.py:handle_request():144] handle_request: stop_status
2023-07-22 14:17:36,034 DEBUG   SenderThread:9548 [sender.py:send_request():396] send_request: stop_status
2023-07-22 14:17:37,280 DEBUG   HandlerThread:9548 [handler.py:handle_request():144] handle_request: status_report
2023-07-22 14:17:42,326 DEBUG   HandlerThread:9548 [handler.py:handle_request():144] handle_request: status_report
